Workbook

Sheet ĐIỀN THÔNG TIN 
A1: Mã Căn | B1: T1.18-02
A2: Dạng Căn | B2: 2 Phòng Ngủ nhỏ
A3: Diện Tích | B3: 61.6
A4: Giá Bán Chưa VAT | B4: 1313439000
A5: Chiết Khấu
A6: Giá VAT | B6: =B4+B4*5% -> 1379110950
A7: Tổng Giá | B7: =B6-B5 -> 1379110950

Sheet CITY VIEW
A2: BẢNG BÁO GIÁ DỰ ÁN NOXH K.HOME CITYVIEW
A3: Mã Căn | C3: ='ĐIỀN THÔNG TIN '!B1 -> T1.18-02
A4: Dạng Căn | C4: ='ĐIỀN THÔNG TIN '!B2 -> 2 Phòng Ngủ nhỏ
A5: Diện Tích | C5: ='ĐIỀN THÔNG TIN '!B3 -> 61.6
A6: Giá Bán Chưa VAT | C6: ='ĐIỀN THÔNG TIN '!B4 -> 1313439000
A7: Giá Bán ( VAT ) | C7: =C6*5%+C6 -> 1379110950
C8: ='ĐIỀN THÔNG TIN '!B5 -> 0
A9: Tổng Giá | C9: =C7-C8 -> 1379110950
A10: BẢNG THANH TOÁN THEO TIẾN ĐỘ
A11: Đợt | B11: Tỷ Lệ % | C11: Thành Tiền | D11: số ngày | E11: Ghi chú
A12: Cọc | C12: 30000000
A13: ĐỢT 1 | B13: 0.15 | C13: =B13*$C$9-C12 -> 1.7686664e+08 | D13: 7
A14: ĐỢT 2 | B14: 0.1 | C14: =B14*$C$9 -> 137911095 | D14: 30 | E14: =C14*D14*15%/365 -> 1700273.8
A15: ĐỢT 3 | B15: 0.05 | C15: =B15*$C$9 -> 68955548 | D15: 60 | E15: =C15*D15*15%/365 -> 1700273.8
A16: ĐỢT 4 | B16: 0.05 | C16: =B16*$C$9 -> 68955548 | D16: 90 | E16: =C16*D16*15%/365 -> 2550410.7
A17: ĐỢT 5 | B17: 0.03 | C17: =B17*$C$9 -> 41373328
A18: ĐỢT 6 | B18: 0.03 | C18: =B18*$C$9 -> 41373328
A19: ĐỢT 7 | B19: 0.03 | C19: =B19*$C$9 -> 41373328
A20: ĐỢT 8 | B20: 0.03 | C20: =B20*$C$9 -> 41373328
A21: ĐỢT 9 | B21: 0.03 | C21: =B21*$C$9 -> 41373328
A22: ĐỢT 10 | B22: 0.03 | C22: =B22*$C$9 -> 41373328
A23: ĐỢT 11 | B23: 0.03 | C23: =B23*$C$9 -> 41373328
A24: ĐỢT 12 | B24: 0.03 | C24: =B24*$C$9 -> 41373328
A25: ĐỢT 13 | B25: 0.03 | C25: =B25*$C$9 -> 41373328
A26: ĐỢT 14 | B26: 0.03 | C26: =B26*$C$9 -> 41373328
A27: ĐỢT 15 | B27: 0.05 | C27: =B27*$C$9 -> 68955548
A28: ĐỢT 16 | B28: 0.25 | C28: =B28*$C$9 -> 3.4477774e+08 | E28: 100% phí bảo trì
A29: ĐỢT 17 | B29: 0.05 | C29: =B29*$C$9 -> 68955548 | E29: Nhận sổ
A30: Tổng Giá | B30: =SUM(B13:B29) -> 1 | C30: =SUM(C12:C29) -> 1379110950
A32: BẢNG THANH TOÁN NOXH THEO VAY NGÂN HÀNG
A33: Mã Căn | C33: =C3 -> T1.18-02 | D33: =C4 -> 2 Phòng Ngủ nhỏ | E33: =C5 -> 61.6
A34: Giá Bán Chưa VAT | C34: =C6 -> 1313439000
A35: Giá Bán ( VAT ) | C35: =C7 -> 1379110950
C36: =C8 -> 0
A37: Tổng Giá | C37: =C35-C36 -> 1379110950
A39: Đợt | B39: KHÁCH HÀNG | C39: NGÂN HÀNG | D39: Thành Tiền | E39: Kỳ hạn thanh toán
A40: Cọc | D40: 30000000 | E40: Đặt Cọc
A41: 1 | B41: 0.15 | D41: =(C37*B41)-D40 -> 1.7686664e+08 | E41: 7 ngày kể từ ngày ký đặt cọc
A42: 2 | B42: 0.05 | D42: =B42*C37 -> 68955548 | E42: 30 ngày kể từ ngày TT đợt 1
A43: 3 | B43: 0.05 | D43: =B43*C37 -> 68955548 | E43: 15 ngày kể từ ngày TB kí HDMB
...

Sheet MIDTOWN
A2: BẢNG BÁO GIÁ DỰ ÁN NOXH K.HOME MIDTOWN
A3: Mã Căn | C3: ='ĐIỀN THÔNG TIN '!B1 -> T1.18-02 | D3: Hồ Mộng Sương SDT : 0933.503052
A4: Dạng Căn | C4: ='ĐIỀN THÔNG TIN '!B2 -> 2 Phòng Ngủ nhỏ
A5: Diện Tích | C5: ='ĐIỀN THÔNG TIN '!B3 -> 61.6
A6: Giá Bán Chưa VAT | C6: ='ĐIỀN THÔNG TIN '!B4 -> 1313439000
A7: Giá Bán ( VAT ) | C7: =C6*5%+C6 -> 1379110950
A8: Chiết Khấu | C8: ='ĐIỀN THÔNG TIN '!B5 -> 0
A9: Tổng Giá | C9: =C7-C8 -> 1379110950
A10: BẢNG THANH TOÁN NOXH THEO TIẾN ĐỘ
A11: Đợt | B11: Tỷ Lệ % | C11: Thành Tiền | D11: số ngày | E11: Ghi chú
A12: Cọc | C12: 30000000
A13: ĐỢT 1 | B13: 0.15 | C13: =B13*$C$9-C12 -> 1.7686664e+08 | D13: 7
A14: ĐỢT 2 | B14: 0.1 | C14: =B14*$C$9 -> 137911095 | D14: 30 | E14: =C14*D14*15%/365 -> 1700273.8
A15: ĐỢT 3 | B15: 0.05 | C15: =B15*$C$9 -> 68955548 | D15: 60 | E15: =C15*D15*15%/365 -> 1700273.8
A16: ĐỢT 4 | B16: 0.05 | C16: =B16*$C$9 -> 68955548 | D16: 90 | E16: =C16*D16*15%/365 -> 2550410.7
A17: ĐỢT 5 | B17: 0.05 | C17: =B17*$C$9 -> 68955548
A18: ĐỢT 6 | B18: 0.05 | C18: =B18*$C$9 -> 68955548
A19: ĐỢT 7 | B19: 0.05 | C19: =B19*$C$9 -> 68955548
A20: ĐỢT 8 | B20: 0.05 | C20: =B20*$C$9 -> 68955548
A21: ĐỢT 9 | B21: 0.05 | C21: =B21*$C$9 -> 68955548
A22: ĐỢT 10 | B22: 0.05 | C22: =B22*$C$9 -> 68955548
A23: ĐỢT 11 | B23: 0.05 | C23: =B23*$C$9 -> 68955548
A24: ĐỢT 12 | B24: 0.25 | C24: =B24*$C$9 -> 3.4477774e+08 | E24: 100% phí bảo trì
A25: ĐỢT 13 | B25: 0.05 | C25: =B25*$C$9 -> 68955548 | E25: Nhận sổ
A26: Tổng Giá | B26: 1 | C26: =SUM(C12:C25) -> 1379110950
A28: BẢNG THANH TOÁN THEO VAY NGÂN HÀNG
A29: Mã Căn | C29: =C3 -> T1.18-02 | D29: =C4 -> 2 Phòng Ngủ nhỏ | E29: =C5 -> 61.6
A30: Giá Bán Chưa VAT | C30: =C6 -> 1313439000 | D30: Đinh Văn Thọ 0938 373 495
A31: Giá Bán ( VAT ) | C31: =C7 -> 1379110950
A32: Chiết Khấu | C32: =C8 -> 0
A33: Tổng Giá | C33: =C31-C32 -> 1379110950
A35: Đợt | B35: KHÁCH HÀNG | C35: NGÂN HÀNG | D35: Thành Tiền | E35: Kỳ hạn thanh toán
A36: Cọc | D36: 30000000 | E36: Đặt Cọc
A37: 1 | B37: 0.15 | D37: =(B37*C33)-D36 -> 1.7686664e+08 | E37: 7 ngày kể từ ngày ký đặt cọc
A38: 2 | B38: 0.1 | D38: =B38*C33 -> 137911095 | E38: 30 ngày kể từ ngày TT đợt 1
A39: 3 | C39: 0.45 | D39: =C39*C33 -> 6.2059993e+08 | E39: Ngân Hàng Giải Ngân Lần 1
A40: 4 | C40: 0.25 | D40: =C40*C33 -> 3.4477774e+08 | E40: Ngân Hàng Giải Ngân Lần 2 KH thanh toán 100% phí bảo trì
A41: 5 | C41: 0.05 | D41: =C33*C41 -> 68955548 | E41: Nhận sổ
A42: Tổng Cộng | B42: =SUM(B36:B41) -> 0.25 | C42: =SUM(C39:C41) -> 0.75 | D42: =SUM(D36:D41) -> 1379110950
B43: =SUM(D36:D38) -> 3.4477774e+08 | C43: =SUM(D39:D41) -> 1.0343332e+09
...

Sheet AVENUE
A2: BẢNG BÁO GIÁ DỰ ÁN NOXH K.HOME AVENUE
A3: Mã Căn | C3: ='ĐIỀN THÔNG TIN '!B1 -> T1.18-02 | D3: Hồ Mộng Sương SDT : 0933.503052
A4: Dạng Căn | C4: ='ĐIỀN THÔNG TIN '!B2 -> 2 Phòng Ngủ nhỏ
A5: Diện Tích | C5: ='ĐIỀN THÔNG TIN '!B3 -> 61.6
A6: Giá Bán Chưa VAT | C6: ='ĐIỀN THÔNG TIN '!B4 -> 1313439000
A7: Giá Bán ( VAT ) | C7: =C6*5%+C6 -> 1379110950
A8: Chiết Khấu | C8: ='ĐIỀN THÔNG TIN '!B5 -> 0
A9: Tổng Giá | C9: =C7-C8 -> 1379110950
A10: BẢNG THANH TOÁN THEO TIẾN ĐỘ
A11: Đợt | B11: Tỷ Lệ % | C11: Thành Tiền | D11: số ngày | E11: Ghi chú
A12: Cọc | C12: 30000000
A13: ĐỢT 1 | B13: 0.15 | C13: =B13*$C$9-C12 -> 1.7686664e+08 | D13: 7
A14: ĐỢT 2 | B14: 0.05 | C14: =B14*$C$9 -> 68955548 | D14: 60 | E14: =C14*D14*15%/365 -> 1700273.8
A15: ĐỢT 3 | B15: 0.05 | C15: =B15*$C$9 -> 68955548 | D15: 120 | E15: =C15*D15*15%/365 -> 3400547.5
A16: ĐỢT 4 | B16: 0.05 | C16: =B16*$C$9 -> 68955548 | D16: 150 | E16: =C16*D16*15%/365 -> 4250684.4
A17: ĐỢT 5 | B17: 0.05 | C17: =B17*$C$9 -> 68955548
A18: ĐỢT 6 | B18: 0.03 | C18: =B18*$C$9 -> 41373328
A19: ĐỢT 7 | B19: 0.03 | C19: =B19*$C$9 -> 41373328
A20: ĐỢT 8 | B20: 0.03 | C20: =B20*$C$9 -> 41373328
A21: ĐỢT 9 | B21: 0.03 | C21: =B21*$C$9 -> 41373328
A22: ĐỢT 10 | B22: 0.03 | C22: =B22*$C$9 -> 41373328
A23: ĐỢT 11 | B23: 0.03 | C23: =B23*$C$9 -> 41373328
A24: ĐỢT 12 | B24: 0.03 | C24: =B24*$C$9 -> 41373328
A25: ĐỢT 13 | B25: 0.03 | C25: =B25*$C$9 -> 41373328
A26: ĐỢT 14 | B26: 0.03 | C26: =B26*$C$9 -> 41373328
A27: ĐỢT 15 | B27: 0.03 | C27: =B27*$C$9 -> 41373328
A28: ĐỢT 16 | B28: 0.05 | C28: =B28*$C$9 -> 68955548
A29: ĐỢT 18 | B29: 0.25 | C29: =B29*$C$9 -> 3.4477774e+08 | E29: KH thanh toán 2% Phí Bảo Trì
A30: ĐỢT 19 | B30: 0.05 | C30: =B30*$C$9 -> 68955548
A31: Tổng Giá | B31: =SUM(B13:B30) -> 1 | C31: =SUM(C12:C30) -> 1379110950
A33: BẢNG THANH TOÁN NOXH THEO VAY NGÂN HÀNG
A34: Mã Căn | C34: =C3 -> T1.18-02 | D34: =C4 -> 2 Phòng Ngủ nhỏ | E34: =C5 -> 61.6
A35: Giá Bán Chưa VAT | C35: =C6 -> 1313439000 | D35: Hồ Mộng Sương 0933.503.052
A36: Giá Bán ( VAT ) | C36: =C7 -> 1379110950
A37: Chiết Khấu | C37: =C8 -> 0
A38: Tổng Giá | C38: =C36-C37 -> 1379110950
A40: Đợt | B40: KHÁCH HÀNG | C40: NGÂN HÀNG | D40: Thành Tiền | E40: Kỳ hạn thanh toán
A41: Cọc | D41: 30000000 | E41: Đặt Cọc
A42: 1 | B42: 0.15 | D42: =(B42*C38)-D41 -> 1.7686664e+08 | E42: 7 ngày kể từ ngày ký đặt cọc
A43: 2 | B43: 0.05 | D43: =B43*C38 -> 68955548 | E43: 30 ngày kể từ ngày TT đợt 1
...

Sheet Lãi Vay
A1: THÔNG TIN KHOẢN VAY | D1: ='ĐIỀN THÔNG TIN '!B1 -> T1.18-02 | E1: ='ĐIỀN THÔNG TIN '!B2 -> 2 Phòng Ngủ nhỏ
A2: Tổng giá (có VAT) | C2: ='ĐIỀN THÔNG TIN '!B7 -> 1379110950
A3: Tổng số tiền vay | B3: 0.75 | C3: =C2*B3 -> 1.0343332e+09
A4: Giải ngân đợt 1 (45%) | B4: 0.45 | C4: =C2*B4 -> 6.2059993e+08 | D4: 46380 | E4: Thời Gian Dự Kiến
A5: Giải ngân đợt 2 (25%) | B5: 0.25 | C5: =C2*B5 -> 3.4477774e+08 | D5: 46836
A6: Giải ngân đợt 3 (5% cuối) | B6: 0.05 | C6: =C2*5% -> 68955548 | D6: =DATE(2029,1,24) -> 47142
A7: Thời gian vay (Tháng) | C7: 300
A8: Lãi suất (%/năm) | C8: 0.054
A10: CHI TIẾT LỊCH THANH TOÁN
A11: Kỳ | B11: Ngày | C11: Dư nợ đầu kỳ | D11: Gốc | E11: Lãi | F11: Tổng thanh toán
A12: 1 | B12: =$D$4 -> 46380 | C12: =$C$4 -> 6.2059993e+08 | D12: =C12/$C$7 -> 2068666.4 | E12: =C12*$C$8/12 -> 2792699.7 | F12: =D12+E12 -> 4861366.1
A13: =A12+1 -> 2 | B13: =EDATE(B12, 1) -> 46411 | C13: =C12-D12+IF(B13=$D$5,$C$5,0)+IF(B13=$D$6,$C$6,0) -> 6.1853126e+08 | D13: =C13/($C$7-A13+1) -> 2068666.4 | E13: =C13*$C$8/12 -> 2783390.7 | F13: =D13+E13 -> 4852057.1
A14: =A13+1 -> 3 | B14: =EDATE(B13, 1) -> 46442 | C14: =C13-D13+IF(B14=$D$5,$C$5,0)+IF(B14=$D$6,$C$6,0) -> 6.1646259e+08 | D14: =C14/($C$7-A14+1) -> 2068666.4 | E14: =(C13-D13)*$C$8/12 -> 2774081.7 | F14: =D14+E14 -> 4842748.1
A15: =A14+1 -> 4 | B15: =EDATE(B14, 1) -> 46470 | C15: =C14-D14+IF(B15=$D$5,$C$5,0)+IF(B15=$D$6,$C$6,0) -> 6.1439393e+08 | D15: =C15/($C$7-A15+1) -> 2068666.4 | E15: =(C14-D14)*$C$8/12 -> 2764772.7 | F15: =D15+E15 -> 4833439.1
A16: =A15+1 -> 5 | B16: =EDATE(B15, 1) -> 46501 | C16: =C15-D15+IF(B16=$D$5,$C$5,0)+IF(B16=$D$6,$C$6,0) -> 6.1232526e+08 | D16: =C16/($C$7-A16+1) -> 2068666.4 | E16: =(C15-D15)*$C$8/12 -> 2755463.7 | F16: =D16+E16 -> 4824130.1
A17: =A16+1 -> 6 | B17: =EDATE(B16, 1) -> 46531 | C17: =C16-D16+IF(B17=$D$5,$C$5,0)+IF(B17=$D$6,$C$6,0) -> 6.102566e+08 | D17: =C17/($C$7-A17+1) -> 2068666.4 | E17: =(C16-D16)*$C$8/12 -> 2746154.7 | F17: =D17+E17 -> 4814821.1
A18: =A17+1 -> 7 | B18: =EDATE(B17, 1) -> 46562 | C18: =C17-D17+IF(B18=$D$5,$C$5,0)+IF(B18=$D$6,$C$6,0) -> 6.0818793e+08 | D18: =C18/($C$7-A18+1) -> 2068666.4 | E18: =(C17-D17)*$C$8/12 -> 2736845.7 | F18: =D18+E18 -> 4805512.1
A19: =A18+1 -> 8 | B19: =EDATE(B18, 1) -> 46592 | C19: =C18-D18+IF(B19=$D$5,$C$5,0)+IF(B19=$D$6,$C$6,0) -> 6.0611926e+08 | D19: =C19/($C$7-A19+1) -> 2068666.4 | E19: =(C18-D18)*$C$8/12 -> 2727536.7 | F19: =D19+E19 -> 4796203.1
A20: =A19+1 -> 9 | B20: =EDATE(B19, 1) -> 46623 | C20: =C19-D19+IF(B20=$D$5,$C$5,0)+IF(B20=$D$6,$C$6,0) -> 6.040506e+08 | D20: =C20/($C$7-A20+1) -> 2068666.4 | E20: =(C19-D19)*$C$8/12 -> 2718227.7 | F20: =D20+E20 -> 4786894.1
A21: =A20+1 -> 10 | B21: =EDATE(B20, 1) -> 46654 | C21: =C20-D20+IF(B21=$D$5,$C$5,0)+IF(B21=$D$6,$C$6,0) -> 6.0198193e+08 | D21: =C21/($C$7-A21+1) -> 2068666.4 | E21: =(C20-D20)*$C$8/12 -> 2708918.7 | F21: =D21+E21 -> 4777585.1
A22: =A21+1 -> 11 | B22: =EDATE(B21, 1) -> 46684 | C22: =C21-D21+IF(B22=$D$5,$C$5,0)+IF(B22=$D$6,$C$6,0) -> 5.9991326e+08 | D22: =C22/($C$7-A22+1) -> 2068666.4 | E22: =(C21-D21)*$C$8/12 -> 2699609.7 | F22: =D22+E22 -> 4768276.1
A23: =A22+1 -> 12 | B23: =EDATE(B22, 1) -> 46715 | C23: =C22-D22+IF(B23=$D$5,$C$5,0)+IF(B23=$D$6,$C$6,0) -> 5.978446e+08 | D23: =C23/($C$7-A23+1) -> 2068666.4 | E23: =(C22-D22)*$C$8/12 -> 2690300.7 | F23: =D23+E23 -> 4758967.1
A24: =A23+1 -> 13 | B24: =EDATE(B23, 1) -> 46745 | C24: =C23-D23+IF(B24=$D$5,$C$5,0)+IF(B24=$D$6,$C$6,0) -> 5.9577593e+08 | D24: =C24/($C$7-A24+1) -> 2068666.4 | E24: =(C23-D23)*$C$8/12 -> 2680991.7 | F24: =D24+E24 -> 4749658.1
A25: =A24+1 -> 14 | B25: =EDATE(B24, 1) -> 46776 | C25: =C24-D24+IF(B25=$D$5,$C$5,0)+IF(B25=$D$6,$C$6,0) -> 5.9370726e+08 | D25: =C25/($C$7-A25+1) -> 2068666.4 | E25: =(C24-D24)*$C$8/12 -> 2671682.7 | F25: =D25+E25 -> 4740349.1
... A311: =A310+1 -> 300 | B311: =EDATE(B310, 1) -> 55481 | C311: =C310-D310+IF(B311=$D$5,$C$5,0)+IF(B311=$D$6,$C$6,0) -> 3529160.3 | D311: =C311/($C$7-A311+1) -> 3529160.3 | E311: =(C310-D310)*$C$8/12 -> 15881.221 | F311: =D311+E311 -> 3545041.5
